Workbook

Sheet Legenda
A1: Technieken-analyse ecdsa.fail (secp256k1 point add), 26-10-2026
A2: Score = gemiddeld uitgevoerde Toffoli x piek-qubits. Leader 9ef3139: 741,645 x 1,234 = 915.2M.
A4: Bladen
A5: Gebruikt: 45 technieken uit alle oplossingen (154 inzendingsnotities gelezen + leader-broncode).
A6: Ongebruikt: 36 quantum-computing technieken die de leader niet gebruikt, incl. recent werk (2024-2026).
A7: Tekstboek: 35 methoden van 2-qubit-poorten tot 256-bit bouwstenen; kolom Opmerking zegt of ze in het nieuwe ontwerp zitten.
A8: Weging: extra eigenschappen + gewichtenmodel (gele cellen aanpasbaar); score per kandidaat is een formule.
A9: Gelijkheid: Gower-gelijkenis van elke kandidaat met elke gebruikte techniek (14 numerieke kenmerken, formules).
A10: Ontwerp: het nieuwe ontwerp zonder leader-constructies, opgebouwd uit primitieven (formules; blauwe cellen = invoer).
A11: Vergelijking: leader, Google (README), gepubliceerd, nieuwe varianten.
A12: Mijlpalen: alle stappen die >=1% van de beste score afhaalden.
A14: Kleuren
... A22: Het ontwerp is een kostenmodel, geen gebouwd circuit: het is niet door eval_circuit gevalideerd.

Sheet Gebruikt
A1: Technieken in alle ingediende oplossingen (inclusief leader)
A3: ID | B3: Techniek | C3: Categorie | D3: Vakgebied | E3: Jaar | F3: Bron | G3: Primair doel | H3: Vast aantal qubits nodig | I3: Extra qubits @256 (schatting) | J3: Ancilla-type | K3: Coherentie-eis (1-5) | L3: Verstrengeling met data nodig | M3: Mid-circuit meting | N3: Klassieke feedforward | O3: Exact / benaderd | P3: Foutkans | Q3: Toffoli-schaal | R3: Qubit-schaal | S3: Diepte-schaal | T3: Challenge-gateset ok | U3: Rotaties nodig | V3: Data-afhankelijk pad | W3: Uncompute-methode | X3: Vooraf berekende tabellen | Y3: Fase-risico | Z3: Complexiteit (1-5) | AA3: Volwassenheid (1-5) | AB3: T-effect op leader (%) | AC3: Q-effect op leader (qubits) | AD3: In leader | AE3: Elders gebruikt | AF3: Opmerking | AH3: f:vast | AI3: f:ancilla | AJ3: f:coherentie | AK3: f:verstrengeling | AL3: f:meting | AM3: f:feedforward | AN3: f:exact | AO3: f:gateset | AP3: f:rotaties | AQ3: f:data-afh | AR3: f:uncompute | AS3: f:tabellen | AT3: f:complexiteit | AU3: f:volwassenheid
A4: G01 | B4: Kaliski binary-GCD inversion (Roetteler two-Kaliski affine point-add) | C4: inversion/GCD | D4: mathematics | E4: 2026 | F4: ecdsa.fail baseline (pre-30c8ded) (challenge baseline, 2026-05-30) | G4: T+Q | H4: ja | I4: - | J4: schoon | K4: 3 | L4: nee | M4: ja | N4: nee | O4: exact | P4: 0 | Q4: O(n^2) | R4: O(n) | S4: O(n^2) | T4: ja | U4: nee | V4: ja | W4: Bennett | X4: nee | Y4: laag | Z4: 4 | AA4: 4 | AB4: - | AC4: - | AD4: nee | AE4: ja | AF4: Baseline: affine point add with two reversible Kaliski binary-GCD modular inversions holding explicit Bezout (r,s) registers. | effect: baseline 10,758,874,395 (derived) = ~3.96M T x 2715 Q; inverse ~79% of Toffoli per f94f726 | Named in f94f726/42d936f notes. Kaliski/dialog code absent from leader (grep). anupsv 1b4e026 tested a single batched inversion (c = dx^3*e) and found it net-negative (+256 peak). | AH4: =IF(H4="ja",1,0) -> 1 | AI4: =IF(J4="schoon",1,IF(J4="vuil",0.5,0)) -> 1 | AJ4: =K4/5 -> 0.6 | AK4: =IF(L4="ja",1,0) -> 0 | AL4: =IF(M4="ja",1,0) -> 1 | AM4: =IF(N4="ja",1,0) -> 0 | AN4: =IF(O4="exact",1,0) -> 1 | AO4: =IF(T4="ja",1,0) -> 1 | AP4: =IF(U4="ja",1,0) -> 0 | AQ4: =IF(V4="ja",1,0) -> 1 | AR4: =IF(W4="Bennett",1,IF(W4="meting",0.5,0)) -> 1 | AS4: =IF(X4="ja",1,0) -> 0 | AT4: =Z4/5 -> 0.8 | AU4: =AA4/5 -> 0.8
A5: G02 | B5: (r,s) cswap boundary merge | C5: scheduling/fusion | D5: computer science | E5: 2026 | F5: ecdsa.fail d35d6e7 (Gajesh2007, 2026-05-31) | G5: T | H5: nee | I5: - | J5: geen | K5: 2 | L5: nee | M5: nee | N5: nee | O5: exact | P5: 0 | Q5: - | R5: - | S5: - | T5: ja | U5: nee | V5: nee | W5: geen | X5: nee | Y5: laag | Z5: 3 | AA5: 3 | AB5: - | AC5: - | AD5: nee | AE5: ja | AF5: Fuse step9(k) and step3(k+1) Bezout conditional swaps across Kaliski iterations via cswap(a)*cswap(b)=cswap(a xor b) with a frame-parity qubit. | effect: -274k Toffoli, peak-neutral; -6.92% vs running best | Kaliski-era only. | AH5: =IF(H5="ja",1,0) -> 0 | AI5: =IF(J5="schoon",1,IF(J5="vuil",0.5,0)) -> 0 | AJ5: =K5/5 -> 0.4 | AK5: =IF(L5="ja",1,0) -> 0 | AL5: =IF(M5="ja",1,0) -> 0 | AM5: =IF(N5="ja",1,0) -> 0 | AN5: =IF(O5="exact",1,0) -> 1 | AO5: =IF(T5="ja",1,0) -> 1 | AP5: =IF(U5="ja",1,0) -> 0 | AQ5: =IF(V5="ja",1,0) -> 0 | AR5: =IF(W5="Bennett",1,IF(W5="meting",0.5,0)) -> 0 | AS5: =IF(X5="ja",1,0) -> 0 | AT5: =Z5/5 -> 0.6 | AU5: =AA5/5 -> 0.6
A6: G03 | B6: (u,v_w) cswap boundary merge on equality-free prefix | C6: scheduling/fusion | D6: computer science | E6: 2026 | F6: ecdsa.fail 112d5a4 (Gajesh2007, 2026-06-01) | G6: T | H6: nee | I6: - | J6: geen | K6: 2 | L6: nee | M6: nee | N6: nee | O6: exact | P6: 0 | Q6: - | R6: - | S6: - | T6: ja | U6: nee | V6: nee | W6: geen | X6: nee | Y6: laag | Z6: 3 | AA6: 3 | AB6: - | AC6: - | AD6: nee | AE6: ja | AF6: Same cswap-fusion identity applied to the GCD operand pair for an early safe prefix of iterations where u != v_w (comparison correction gt ^= frame valid). | effect: -7.19% vs running best (T 3.64M->3.36M at 2310 Q) | Safe-prefix length later extended (0a0a631: 254->255; d1d29eb 329->331) with reroll co-tuning. | AH6: =IF(H6="ja",1,0) -> 0 | AI6: =IF(J6="schoon",1,IF(J6="vuil",0.5,0)) -> 0 | AJ6: =K6/5 -> 0.4 | AK6: =IF(L6="ja",1,0) -> 0 | AL6: =IF(M6="ja",1,0) -> 0 | AM6: =IF(N6="ja",1,0) -> 0 | AN6: =IF(O6="exact",1,0) -> 1 | AO6: =IF(T6="ja",1,0) -> 1 | AP6: =IF(U6="ja",1,0) -> 0 | AQ6: =IF(V6="ja",1,0) -> 0 | AR6: =IF(W6="Bennett",1,IF(W6="meting",0.5,0)) -> 0 | AS6: =IF(X6="ja",1,0) -> 0 | AT6: =Z6/5 -> 0.6 | AU6: =AA6/5 -> 0.6
A7: G04 | B7: Carry/scratch hosting on provably-|0> or idle wires | C7: width/qubit management | D7: computer science | E7: 2026 | F7: ecdsa.fail f94f726 (Gajesh2007, 2026-05-31) | G7: Q | H7: nee | I7: - | J7: vuil | K7: 2 | L7: nee | M7: ja | N7: nee | O7: benaderd | P7: per shot (lambda) | Q7: O(1) | R7: - | S7: - | T7: ja | U7: nee | V7: nee | W7: meting | X7: nee | Y7: midden | Z7: 3 | AA7: 3 | AB7: - | AC7: - | AD7: deels | AE7: ja | AF7: Borrow adder carry lanes and history bits from registers proven zero at that instant (future history bits, shrinking high bits of u/v/s/r, idle transcript/future-log slots) instead of dedicated ancilla. | effect: f94f726: -126k T (late carry recovery) and peak 2459->2333 (9n floor); 0620443 C*/dialog-fold: peak 2309->2025; 744b274 host-gated: 1698->1572 (with windowed apply); 53cab17/40e10ac: 1466->1446; 62c8115 composite scratch: ->1355 | Merged family: late-iteration carry recovery, 9n carry-borrow, dialog history-fold into v_w high bits, C* carry-pool relocation (0620443), HOST_GATED/compos | AH7: =IF(H7="ja",1,0) -> 0 | AI7: =IF(J7="schoon",1,IF(J7="vuil",0.5,0)) -> 0.5 | AJ7: =K7/5 -> 0.4 | AK7: =IF(L7="ja",1,0) -> 0 | AL7: =IF(M7="ja",1,0) -> 1 | AM7: =IF(N7="ja",1,0) -> 0 | AN7: =IF(O7="exact",1,0) -> 0 | AO7: =IF(T7="ja",1,0) -> 1 | AP7: =IF(U7="ja",1,0) -> 0 | AQ7: =IF(V7="ja",1,0) -> 0 | AR7: =IF(W7="Bennett",1,IF(W7="meting",0.5,0)) -> 0.5 | AS7: =IF(X7="ja",1,0) -> 0 | AT7: =Z7/5 -> 0.6 | AU7: =AA7/5 -> 0.6
A8: G05 | B8: Joint-pin peak analysis / peak-owner tracing and qubit-cap retuning | C8: width/qubit management | D8: computer science | E8: 2026 | F8: ecdsa.fail f94f726 (Gajesh2007, 2026-05-31) | G8: Q | H8: nee | I8: - | J8: vuil | K8: 2 | L8: nee | M8: nee | N8: nee | O8: exact | P8: 0 | Q8: O(1) | R8: - | S8: - | T8: ja | U8: nee | V8: nee | W8: geen | X8: nee | Y8: midden | Z8: 3 | AA8: 3 | AB8: 0 | AC8: 0 | AD8: ja | AE8: ja | AF8: Treat the peak as a tie of several co-resident clusters, trace binders per phase, attack all together; later pin an explicit walk cap and retune cap vs reorder for the Q x T optimum. | effect: f94f726 plateau break 2708->2565->2459; c8f6ff0 measured cap 1263->1260; 6e00c30 cap 1239->1244 (+5 Q, -3.5k T) net -0.03% | Methodology plus knobs; break-even quoted as ~640-723 Toffoli per qubit at ~1.24k Q (6e00c30, 21a0ba3). Majority packing / cap-1234 retiming by mochimodev (a362dca) credited in 076f110, not read. | AH8: =IF(H8="ja",1,0) -> 0 | AI8: =IF(J8="schoon",1,IF(J8="vuil",0.5,0)) -> 0.5 | AJ8: =K8/5 -> 0.4 | AK8: =IF(L8="ja",1,0) -> 0 | AL8: =IF(M8="ja",1,0) -> 0 | AM8: =IF(N8="ja",1,0) -> 0 | AN8: =IF(O8="exact",1,0) -> 1 | AO8: =IF(T8="ja",1,0) -> 1 | AP8: =IF(U8="ja",1,0) -> 0 | AQ8: =IF(V8="ja",1,0) -> 0 | AR8: =IF(W8="Bennett",1,IF(W8="meting",0.5,0)) -> 0 | AS8: =IF(X8="ja",1,0) -> 0 | AT8: =Z8/5 -> 0.6 | AU8: =AA8/5 -> 0.6
A9: G06 | B9: Iteration / round-count trimming | C9: approximation | D9: statistics | E9: 2026 | F9: ecdsa.fail c8f4367 (mmurrs, 2026-05-31) | G9: T | H9: nee | I9: - | J9: geen | K9: 1 | L9: nee | M9: nee | N9: nee | O9: benaderd | P9: per shot (lambda) | Q9: - | R9: - | S9: - | T9: ja | U9: nee | V9: ja | W9: geen | X9: nee | Y9: laag | Z9: 2 | AA9: 3 | AB9: - | AC9: - | AD9: deels | AE9: ja | AF9: Lower the fixed number of GCD iterations/rounds/ticks to the empirical convergence tail, co-tuned with the test island. | effect: per step: e.g. 42d936f -14k T (pair2 401->397); 40e10ac ACTIVE 399->397 -4.3k T; ~3k T per step in 1153Q route (b87bdf7) | PR 419/mochimodev limiting contract (8186402) forbids pure round reductions as error-for-score trades; 02146ca deliberately ADDED 3 divsteps (258->261) to buy lambda. | AH9: =IF(H9="ja",1,0) -> 0 | AI9: =IF(J9="schoon",1,IF(J9="vuil",0.5,0)) -> 0 | AJ9: =K9/5 -> 0.2 | AK9: =IF(L9="ja",1,0) -> 0 | AL9: =IF(M9="ja",1,0) -> 0 | AM9: =IF(N9="ja",1,0) -> 0 | AN9: =IF(O9="exact",1,0) -> 0 | AO9: =IF(T9="ja",1,0) -> 1 | AP9: =IF(U9="ja",1,0) -> 0 | AQ9: =IF(V9="ja",1,0) -> 1 | AR9: =IF(W9="Bennett",1,IF(W9="meting",0.5,0)) -> 0 | AS9: =IF(X9="ja",1,0) -> 0 | AT9: =Z9/5 -> 0.4 | AU9: =AA9/5 -> 0.6
A10: G07 | B10: W-TRUNC empirical width-envelope truncation | C10: approximation | D10: statistics | E10: 2026 | F10: ecdsa.fail 437e22a (Gajesh2007, 2026-06-01) | G10: T | H10: nee | I10: - | J10: geen | K10: 1 | L10: nee | M10: nee | N10: nee | O10: benaderd | P10: per shot (lambda) | Q10: - | R10: - | S10: - | T10: ja | U10: nee | V10: ja | W10: geen | X10: nee | Y10: laag | Z10: 2 | AA10: 3 | AB10: 0 | AC10: 0 | AD10: ja | AE10: ja | AF10: Size each GCD-step width loop (OR chain, comparator, add/sub) to a fitted empirical bit-length envelope + margin instead of the provable worst case. | effect: -8.73% vs running best (T 3.36M->3.06M); margin/K0 retunes 70699b7 -1.56%, 4a11f65 -1.38%, 03499c8 -1.46%; dialog-era width margin/slope 37816e7 -1.31%, 730949a -1.14%, 64f75ba -1.80% | Family includes Kaliski W-TRUNC, dialog-GCD active-width margin/slope (08573bd), ping-pong SLOPE_2 (9dcbdb8), leapfrog joint 'peeling' envelope fit on 1.92M walks (53986ea). Failures surface as classical mismatches. | AH10: =IF(H10="ja",1,0) -> 0 | AI10: =IF(J10="schoon",1,IF(J10="vuil",0.5,0)) -> 0 | AJ10: =K10/5 -> 0.2 | AK10: =IF(L10="ja",1,0) -> 0 | AL10: =IF(M10="ja",1,0) -> 0 | AM10: =IF(N10="ja",1,0) -> 0 | AN10: =IF(O10="exact",1,0) -> 0 | AO10: =IF(T10="ja",1,0) -> 1 | AP10: =IF(U10="ja",1,0) -> 0 | AQ10: =IF(V10="ja",1,0) -> 1 | AR10: =IF(W10="Bennett",1,IF(W10="meting",0.5,0)) -> 0 | AS10: =IF(X10="ja",1,0) -> 0 | AT10: =Z10/5 -> 0.4 | AU10: =AA10/5 -> 0.6
A11: G08 | B11: Realizable-width truncation of conditional swaps | C11: approximation | D11: statistics | E11: 2026 | F11: ecdsa.fail 2ca410f (Gajesh2007, 2026-06-01) | G11: T | H11: nee | I11: - | J11: geen | K11: 1 | L11: nee | M11: nee | N11: nee | O11: benaderd | P11: per shot (lambda) | Q11: - | R11: - | S11: - | T11: ja | U11: nee | V11: ja | W11: geen | X11: nee | Y11: laag | Z11: 2 | AA11: 3 | AB11: - | AC11: - | AD11: nee | AE11: ja | AF11: Truncate the Kaliski STEP-3/9 (u,v_w) conditional swaps to the W-TRUNC width + margin instead of the invariant 2n-iter. | effect: -212,688 emitted CCX (-7.5%); -6.41% vs running best | cswaps were ~27% of Toffoli. Leapfrog's fixed alternating roles remove data-dependent swaps entirely. | AH11: =IF(H11="ja",1,0) -> 0 | AI11: =IF(J11="schoon",1,IF(J11="vuil",0.5,0)) -> 0 | AJ11: =K11/5 -> 0.2 | AK11: =IF(L11="ja",1,0) -> 0 | AL11: =IF(M11="ja",1,0) -> 0 | AM11: =IF(N11="ja",1,0) -> 0 | AN11: =IF(O11="exact",1,0) -> 0 | AO11: =IF(T11="ja",1,0) -> 1 | AP11: =IF(U11="ja",1,0) -> 0 | AQ11: =IF(V11="ja",1,0) -> 1 | AR11: =IF(W11="Bennett",1,IF(W11="meting",0.5,0)) -> 0 | AS11: =IF(X11="ja",1,0) -> 0 | AT11: =Z11/5 -> 0.4 | AU11: =AA11/5 -> 0.6
A12: G09 | B12: Carry-tail / fold-window truncation for the sparse constant f=2^32+977 | C12: approximation | D12: statistics | E12: 2026 | F12: ecdsa.fail 037fd71 (Gajesh2007, 2026-06-01) | G12: T | H12: nee | I12: - | J12: geen | K12: 1 | L12: nee | M12: ja | N12: nee | O12: benaderd | P12: per shot (lambda) | Q12: - | R12: - | S12: - | T12: ja | U12: nee | V12: ja | W12: meting | X12: nee | Y12: laag | Z12: 2 | AA12: 3 | AB12: 0 | AC12: 0 | AD12: ja | AE12: ja | AF12: In +-c constant adders and pseudo-Mersenne folds, cut the carry/borrow ripple a window W above bit 32; propagation beyond has probability ~2^-W. | effect: -2.04% vs running best (037fd71); W 96->59 f751e0b -0.49%; DIRECT_CONST_DOUBLE routing 375fdff -3.32%; apply-phase double/halve trunc 66ad478 (-152,520 T) | solimander 22bae60 found it unsound for the dense constant p+1 and added a constant-aware window. 375fdff routed mod_double through the register-free direct const-add so truncation applies. 21a0ba3 argues ENDPOINT_FOLD_WINDOW 54->40 is 'provably lambda-free' (~2^-40). | AH12: =IF(H12="ja",1,0) -> 0 | AI12: =IF(J12="schoon",1,IF(J12="vuil",0.5,0)) -> 0 | AJ12: =K12/5 -> 0.2 | AK12: =IF(L12="ja",1,0) -> 0 | AL12: =IF(M12="ja",1,0) -> 1 | AM12: =IF(N12="ja",1,0) -> 0 | AN12: =IF(O12="exact",1,0) -> 0 | AO12: =IF(T12="ja",1,0) -> 1 | AP12: =IF(U12="ja",1,0) -> 0 | AQ12: =IF(V12="ja",1,0) -> 1 | AR12: =IF(W12="Bennett",1,IF(W12="meting",0.5,0)) -> 0.5 | AS12: =IF(X12="ja",1,0) -> 0 | AT12: =Z12/5 -> 0.4 | AU12: =AA12/5 -> 0.6
A13: G10 | B13: Correction-free doubling for small r (R_SMALL threshold) | C13: reduction | D13: mathematics | E13: 2026 | F13: ecdsa.fail 42d936f (bxue-l2, 2026-06-01) | G13: T | H13: ja | I13: - | J13: schoon | K13: 2 | L13: nee | M13: nee | N13: nee | O13: benaderd | P13: per shot (lambda) | Q13: O(n) | R13: O(n) | S13: O(n) | T13: ja | U13: nee | V13: nee | W13: Bennett | X13: ja | Y13: laag | Z13: 3 | AA13: 4 | AB13: - | AC13: - | AD13: nee | AE13: ja | AF13: In early Kaliski iterations where r is provably/empirically small, replace mod_double(r) by a plain shift (no reduction). | effect: ~255 CCX per affected iteration (ea4f6e0); mostly used as a re-roll knob | Pre-existing in the tree when first mentioned (R_SMALL_THRESHOLD=326); origin not read. Kaliski-era only. | AH13: =IF(H13="ja",1,0) -> 1 | AI13: =IF(J13="schoon",1,IF(J13="vuil",0.5,0)) -> 1 | AJ13: =K13/5 -> 0.4 | AK13: =IF(L13="ja",1,0) -> 0 | AL13: =IF(M13="ja",1,0) -> 0 | AM13: =IF(N13="ja",1,0) -> 0 | AN13: =IF(O13="exact",1,0) -> 0 | AO13: =IF(T13="ja",1,0) -> 1 | AP13: =IF(U13="ja",1,0) -> 0 | AQ13: =IF(V13="ja",1,0) -> 0 | AR13: =IF(W13="Bennett",1,IF(W13="meting",0.5,0)) -> 1 | AS13: =IF(X13="ja",1,0) -> 1 | AT13: =Z13/5 -> 0.6 | AU13: =AA13/5 -> 0.8
A14: G11 | B14: Fiat-Shamir reroll / identity-tail nonce island selection | C14: validation/nonce | D14: cryptography | E14: 2026 | F14: ecdsa.fail 0ae959c (Epistetechnician, 2026-06-02) | G14: geen | H14: nee | I14: - | J14: geen | K14: 1 | L14: nee | M14: nee | N14: nee | O14: benaderd | P14: per shot (lambda) | Q14: - | R14: - | S14: - | T14: ja | U14: nee | V14: nee | W14: geen | X14: nee | Y14: laag | Z14: 2 | AA14: 3 | AB14: 0 | AC14: 0 | AD14: ja | AE14: ja | AF14: Append identity X;X pairs whose targets encode a nonce; this changes the SHAKE256 hash of the op stream and so re-draws the 9,024 test inputs without changing the circuit. Pick a nonce on which every shot passes. | effect: no direct T/Q change; enables every truncation. Nonce also moves avg executed T by ~10-15k band (b5fa90f, 7bb8713) | First seen as KAL_REROLL (0ae959c; Gajesh 2a05eae and 08573bd describe the 'island lottery'). Fixed-length 96-op tail with prefix-hash reuse introduced by stevenhao f026481 (2026-06-04); compact base-1024 tail by swadhin 6f8aba7. jtrose24 f1acd7f flags the int | AH14: =IF(H14="ja",1,0) -> 0 | AI14: =IF(J14="schoon",1,IF(J14="vuil",0.5,0)) -> 0 | AJ14: =K14/5 -> 0.2 | AK14: =IF(L14="ja",1,0) -> 0 | AL14: =IF(M14="ja",1,0) -> 0 | AM14: =IF(N14="ja",1,0) -> 0 | AN14: =IF(O14="exact",1,0) -> 0 | AO14: =IF(T14="ja",1,0) -> 1 | AP14: =IF(U14="ja",1,0) -> 0 | AQ14: =IF(V14="ja",1,0) -> 0 | AR14: =IF(W14="Bennett",1,IF(W14="meting",0.5,0)) -> 0 | AS14: =IF(X14="ja",1,0) -> 0 | AT14: =Z14/5 -> 0.4 | AU14: =AA14/5 -> 0.6
A15: G12 | B15: Classical prefilter + GPU nonce search pipeline | C15: validation/nonce | D15: cryptography | E15: 2026 | F15: ecdsa.fail 823b7cf (zuiris, 2026-06-05) | G15: geen | H15: nee | I15: - | J15: geen | K15: 1 | L15: nee | M15: nee | N15: nee | O15: exact | P15: 0 | Q15: - | R15: - | S15: - | T15: ja | U15: nee | V15: nee | W15: geen | X15: nee | Y15: laag | Z15: 2 | AA15: 3 | AB15: - | AC15: - | AD15: nee | AE15: ja | AF15: Bit-exact classical replay of the GCD/walk (and later phase-repair sites) on candidate nonces, GPU-parallel, with survivors confirmed by the trusted 9,024-shot evaluator. | effect: search cost only; e.g. 9e1ab6a scanned 2.3e10 seeds on ~28 RTX 4090s; 6e00c30 expects ~1.2e8 nonces at lambda 18.6 | External tooling, not in src/point_add. Jieyi Long's public ecdsafail_gpu_toolkit credited from ca5f0c3 onward. Input derivation reimplemented with Jacobian + comb + Montgomery batch inversion. | AH15: =IF(H15="ja",1,0) -> 0 | AI15: =IF(J15="schoon",1,IF(J15="vuil",0.5,0)) -> 0 | AJ15: =K15/5 -> 0.2 | AK15: =IF(L15="ja",1,0) -> 0 | AL15: =IF(M15="ja",1,0) -> 0 | AM15: =IF(N15="ja",1,0) -> 0 | AN15: =IF(O15="exact",1,0) -> 1 | AO15: =IF(T15="ja",1,0) -> 1 | AP15: =IF(U15="ja",1,0) -> 0 | AQ15: =IF(V15="ja",1,0) -> 0 | AR15: =IF(W15="Bennett",1,IF(W15="meting",0.5,0)) -> 0 | AS15: =IF(X15="ja",1,0) -> 0 | AT15: =Z15/5 -> 0.4 | AU15: =AA15/5 -> 0.6
A16: G13 | B16: Lambda budget economics and limiting contract | C16: validation/nonce | D16: cryptography | E16: 2026 | F16: ecdsa.fail 02146ca (Gajesh2007, 2026-07-26) | G16: geen | H16: nee | I16: - | J16: geen | K16: 1 | L16: nee | M16: nee | N16: nee | O16: exact | P16: 0 | Q16: - | R16: - | S16: - | T16: ja | U16: nee | V16: nee | W16: geen | X16: nee | Y16: laag | Z16: 2 | AA16: 3 | AB16: - | AC16: - | AD16: deels | AE16: ja | AF16: Model failing shots per 9,024 as Poisson lambda (classical + phase); minimise score subject to lambda being grindable; buy lambda back with exact cuts and spend it where Toffoli-per-lambda is highest. | effect: 02146ca measured head lambda_total=23.29, P(clean)=7.7e-11; 9dcbdb8 trade table (ROUNDS_MUL -6 vs -2: 10.6x hunt cost); contract caps lambda at 18, later 19.5 | Methodology, not a gate-level technique. Social rule introduced with PR 419 (8186402, mochimodev, 2026-09-25): lambda<=18 on 9,024 shots, no direct error-for-score trades; later raised to 19.5 after Telegram discussion. | AH16: =IF(H16="ja",1,0) -> 0 | AI16: =IF(J16="schoon",1,IF(J16="vuil",0.5,0)) -> 0 | AJ16: =K16/5 -> 0.2 | AK16: =IF(L16="ja",1,0) -> 0 | AL16: =IF(M16="ja",1,0) -> 0 | AM16: =IF(N16="ja",1,0) -> 0 | AN16: =IF(O16="exact",1,0) -> 1 | AO16: =IF(T16="ja",1,0) -> 1 | AP16: =IF(U16="ja",1,0) -> 0 | AQ16: =IF(V16="ja",1,0) -> 0 | AR16: =IF(W16="Bennett",1,IF(W16="meting",0.5,0)) -> 0 | AS16: =IF(X16="ja",1,0) -> 0 | AT16: =Z16/5 -> 0.4 | AU16: =AA16/5 -> 0.6
A17: G14 | B17: Measurement-based uncomputation (Gidney HMR + classically-controlled CZ) | C17: uncomputation | D17: physics | E17: 2026 | F17: ecdsa.fail c8f4367 (mmurrs, 2026-05-31) | G17: T | H17: nee | I17: - | J17: geen | K17: 1 | L17: nee | M17: ja | N17: ja | O17: exact | P17: 0 | Q17: O(n) | R17: O(1) | S17: O(n) | T17: ja | U17: nee | V17: nee | W17: meting | X17: nee | Y17: hoog | Z17: 3 | AA17: 4 | AB17: 0 | AC17: 0 | AD17: ja | AE17: ja | AF17: Uncompute AND ancillas and adder carry lanes by X-basis measurement plus a measurement-conditioned phase fix (0 Toffoli) instead of a mirrored Toffoli sweep. | effect: 75927ba comparator -209,520 T (-7.21%); df59687 sub-clear + comparator fast-eval (-6.27%); 1f7aabe apply sub -102k T (-4.90%); 690bdb9/8ee9ad8 -23.9k T each | c8f4367 already uses a 'measurement-uncomputed fast Cuccaro' path; origin earlier than read notes. Value-exact; failures only if phase fix is wrong. | AH17: =IF(H17="ja",1,0) -> 0 | AI17: =IF(J17="schoon",1,IF(J17="vuil",0.5,0)) -> 0 | AJ17: =K17/5 -> 0.2 | AK17: =IF(L17="ja",1,0) -> 0 | AL17: =IF(M17="ja",1,0) -> 1 | AM17: =IF(N17="ja",1,0) -> 1 | AN17: =IF(O17="exact",1,0) -> 1 | AO17: =IF(T17="ja",1,0) -> 1 | AP17: =IF(U17="ja",1,0) -> 0 | AQ17: =IF(V17="ja",1,0) -> 0 | AR17: =IF(W17="Bennett",1,IF(W17="meting",0.5,0)) -> 0.5 | AS17: =IF(X17="ja",1,0) -> 0 | AT17: =Z17/5 -> 0.6 | AU17: =AA17/5 -> 0.8
A18: G15 | B18: Dialog-GCD: record-and-replay transcript instead of Bezout registers | C18: inversion/GCD | D18: mathematics | E18: 2026 | F18: ecdsa.fail 0c1d4d9 (pldallairedemers, 2026-06-02) | G18: T+Q | H18: ja | I18: - | J18: schoon | K18: 3 | L18: nee | M18: ja | N18: nee | O18: exact | P18: 0 | Q18: O(n^2) | R18: O(n) | S18: O(n^2) | T18: ja | U18: nee | V18: ja | W18: Bennett | X18: nee | Y18: laag | Z18: 4 | AA18: 4 | AB18: - | AC18: - | AD18: deels | AE18: ja | AF18: Run the binary GCD forward recording per-step branch decisions in a sidecar log, replay the log to apply the quotient to the payload, then reverse; no explicit (r,s) cofactor registers. | effect: -18.83% vs running best; peak 2006->1698, T 2.55M->2.45M | Ported 'TensorFurnace' framework (note is short). Lineage: dialog-GCD -> K=2 jump -> trailmix -> ping-pong -> Skywalk -> Leapfrog all record a transcript and replay it on the payload. | AH18: =IF(H18="ja",1,0) -> 1 | AI18: =IF(J18="schoon",1,IF(J18="vuil",0.5,0)) -> 1 | AJ18: =K18/5 -> 0.6 | AK18: =IF(L18="ja",1,0) -> 0 | AL18: =IF(M18="ja",1,0) -> 1 | AM18: =IF(N18="ja",1,0) -> 0 | AN18: =IF(O18="exact",1,0) -> 1 | AO18: =IF(T18="ja",1,0) -> 1 | AP18: =IF(U18="ja",1,0) -> 0 | AQ18: =IF(V18="ja",1,0) -> 1 | AR18: =IF(W18="Bennett",1,IF(W18="meting",0.5,0)) -> 1 | AS18: =IF(X18="ja",1,0) -> 0 | AT18: =Z18/5 -> 0.8 | AU18: =AA18/5 -> 0.8
A19: G16 | B19: Transcript compression codecs | C19: encoding/transcript | D19: information theory | E19: 2026 | F19: ecdsa.fail 0c1d4d9 (pldallairedemers, 2026-06-02) | G19: Q | H19: ja | I19: - | J19: schoon | K19: 2 | L19: nee | M19: nee | N19: nee | O19: exact | P19: 0 | Q19: O(n) | R19: O(n) | S19: O(n) | T19: ja | U19: nee | V19: ja | W19: Bennett | X19: nee | Y19: laag | Z19: 3 | AA19: 3 | AB19: - | AC19: - | AD19: deels | AE19: ja | AF19: Pack the GCD decision transcript below 1 qubit per raw bit using reachability constraints (compressed sidecar blocks, K2 pair 6->5 bits, base-5 triples 9->7 bits, Skywalk ternary 5 steps in 8 qubits, SAT-synthesized in-place pairs core). | effect: 351373f K2 pair compressor: drops to 1313 Q tier; af5abb1 tob-joe: resident tape 603q vs ~775 raw | Inline/streamed compression so the raw tape never exists (af5abb1). | AH19: =IF(H19="ja",1,0) -> 1 | AI19: =IF(J19="schoon",1,IF(J19="vuil",0.5,0)) -> 1 | AJ19: =K19/5 -> 0.4 | AK19: =IF(L19="ja",1,0) -> 0 | AL19: =IF(M19="ja",1,0) -> 0 | AM19: =IF(N19="ja",1,0) -> 0 | AN19: =IF(O19="exact",1,0) -> 1 | AO19: =IF(T19="ja",1,0) -> 1 | AP19: =IF(U19="ja",1,0) -> 0 | AQ19: =IF(V19="ja",1,0) -> 1 | AR19: =IF(W19="Bennett",1,IF(W19="meting",0.5,0)) -> 1 | AS19: =IF(X19="ja",1,0) -> 0 | AT19: =Z19/5 -> 0.6 | AU19: =AA19/5 -> 0.6
A20: G17 | B20: Truncated top-window comparators | C20: approximation | D20: statistics | E20: 2026 | F20: ecdsa.fail 0c1d4d9 (pldallairedemers, 2026-06-02) | G20: T | H20: nee | I20: - | J20: geen | K20: 1 | L20: nee | M20: nee | N20: nee | O20: benaderd | P20: per shot (lambda) | Q20: - | R20: - | S20: - | T20: ja | U20: nee | V20: ja | W20: geen | X20: nee | Y20: laag | Z20: 2 | AA20: 3 | AB20: 0 | AC20: 0 | AD20: ja | AE20: ja | AF20: Decide branch (u>v), flag and chunk-boundary predicates using only the top k bits of the active window, with per-step schedules. | effect: 4ac4a16 72->68 (~20k T); f1acd7f 75->63 (-1.48%); 66ad478 per-step schedule (-5,384 T); leapfrog W1 24->18 bits (a02c716) | Many single-bit retunes (COMPARE_BITS 59..44, APPLY_CLEAN 22..18, REPLAY_CHUNK_COMPARE 26->21) are the same family. | AH20: =IF(H20="ja",1,0) -> 0 | AI20: =IF(J20="schoon",1,IF(J20="vuil",0.5,0)) -> 0 | AJ20: =K20/5 -> 0.2 | AK20: =IF(L20="ja",1,0) -> 0 | AL20: =IF(M20="ja",1,0) -> 0 | AM20: =IF(N20="ja",1,0) -> 0 | AN20: =IF(O20="exact",1,0) -> 0 | AO20: =IF(T20="ja",1,0) -> 1 | AP20: =IF(U20="ja",1,0) -> 0 | AQ20: =IF(V20="ja",1,0) -> 1 | AR20: =IF(W20="Bennett",1,IF(W20="meting",0.5,0)) -> 0 | AS20: =IF(X20="ja",1,0) -> 0 | AT20: =Z20/5 -> 0.4 | AU20: =AA20/5 -> 0.6
A21: G18 | B21: Fused branch-bit comparator | C21: scheduling/fusion | D21: computer science | E21: 2026 | F21: ecdsa.fail fd70a60 (Epistetechnician, 2026-06-02) | G21: T | H21: nee | I21: - | J21: geen | K21: 2 | L21: nee | M21: nee | N21: nee | O21: exact | P21: 0 | Q21: - | R21: - | S21: - | T21: ja | U21: nee | V21: nee | W21: geen | X21: nee | Y21: laag | Z21: 3 | AA21: 3 | AB21: - | AC21: - | AD21: nee | AE21: ja | AF21: Emit b0 AND b1 directly under the control from the in-flight comparator carry, avoiding an intermediate compare qubit and its uncompute. | effect: -3.32% vs running best (T 1.93M->1.86M) | f2cd713 later hosted this comparator's carry lane on future-log slots (peak 1500->1466). | AH21: =IF(H21="ja",1,0) -> 0 | AI21: =IF(J21="schoon",1,IF(J21="vuil",0.5,0)) -> 0 | AJ21: =K21/5 -> 0.4 | AK21: =IF(L21="ja",1,0) -> 0 | AL21: =IF(M21="ja",1,0) -> 0 | AM21: =IF(N21="ja",1,0) -> 0 | AN21: =IF(O21="exact",1,0) -> 1 | AO21: =IF(T21="ja",1,0) -> 1 | AP21: =IF(U21="ja",1,0) -> 0 | AQ21: =IF(V21="ja",1,0) -> 0 | AR21: =IF(W21="Bennett",1,IF(W21="meting",0.5,0)) -> 0 | AS21: =IF(X21="ja",1,0) -> 0 | AT21: =Z21/5 -> 0.6 | AU21: =AA21/5 -> 0.6
A22: G19 | B22: Chunked/windowed adders with measured boundary-carry erasure | C22: adder | D22: computer science | E22: 2026 | F22: ecdsa.fail 744b274 (saucegodbased, 2026-06-02) | G22: T | H22: ja | I22: - | J22: schoon | K22: 2 | L22: nee | M22: ja | N22: nee | O22: benaderd | P22: per shot (lambda) | Q22: O(n) | R22: O(n) | S22: O(n) | T22: ja | U22: nee | V22: nee | W22: meting | X22: nee | Y22: laag | Z22: 2 | AA22: 5 | AB22: 0 | AC22: 0 | AD22: ja | AE22: ja | AF22: Split a wide ripple add into blocks so the full carry lane never coexists with other wide registers; clear each block-boundary carry by HMR plus a (truncated) comparator repair. | effect: 744b274: peak 1698->1572 (+102k T); 3bd3aa5 chunked f-materialization -3.09%; 67be862 apply teardown 1382->1320 Q | Boundary repair compares are a truncation (2^-k per boundary, k~21-25). Later refinements: lazy carry-out allocation and eager boundary erasure (21a0ba3), budgeted chunk count per round (bc7a792). | AH22: =IF(H22="ja",1,0) -> 1 | AI22: =IF(J22="schoon",1,IF(J22="vuil",0.5,0)) -> 1 | AJ22: =K22/5 -> 0.4 | AK22: =IF(L22="ja",1,0) -> 0 | AL22: =IF(M22="ja",1,0) -> 1 | AM22: =IF(N22="ja",1,0) -> 0 | AN22: =IF(O22="exact",1,0) -> 0 | AO22: =IF(T22="ja",1,0) -> 1 | AP22: =IF(U22="ja",1,0) -> 0 | AQ22: =IF(V22="ja",1,0) -> 0 | AR22: =IF(W22="Bennett",1,IF(W22="meting",0.5,0)) -> 0.5 | AS22: =IF(X22="ja",1,0) -> 0 | AT22: =Z22/5 -> 0.4 | AU22: =AA22/5 -> 1
A23: G20 | B23: Odd low-bit / parked constant bit 0 | C23: width/qubit management | D23: computer science | E23: 2026 | F23: ecdsa.fail 73f81cc (Epistetechnician, 2026-06-02) | G23: Q | H23: nee | I23: - | J23: vuil | K23: 2 | L23: nee | M23: nee | N23: nee | O23: exact | P23: 0 | Q23: O(1) | R23: - | S23: - | T23: ja | U23: nee | V23: nee | W23: geen | X23: nee | Y23: midden | Z23: 3 | AA23: 3 | AB23: 0 | AC23: 0 | AD23: ja | AE23: ja | AF23: Odd operands have bit 0 = 1 on the reachable path: replace CCX by CX on lane 0, skip lane-0 swaps, and later park bit 0 off-register for the whole walk. | effect: ~-3,192 T (b54d856); c8f6ff0 parked bit 0: -274 executed T; frees 2 walk wires | Exact on the reachable support. | AH23: =IF(H23="ja",1,0) -> 0 | AI23: =IF(J23="schoon",1,IF(J23="vuil",0.5,0)) -> 0.5 | AJ23: =K23/5 -> 0.4 | AK23: =IF(L23="ja",1,0) -> 0 | AL23: =IF(M23="ja",1,0) -> 0 | AM23: =IF(N23="ja",1,0) -> 0 | AN23: =IF(O23="exact",1,0) -> 1 | AO23: =IF(T23="ja",1,0) -> 1 | AP23: =IF(U23="ja",1,0) -> 0 | AQ23: =IF(V23="ja",1,0) -> 0 | AR23: =IF(W23="Bennett",1,IF(W23="meting",0.5,0)) -> 0 | AS23: =IF(X23="ja",1,0) -> 0 | AT23: =Z23/5 -> 0.6 | AU23: =AA23/5 -> 0.6
A24: G21 | B24: Affine square-recompute and lambda^2 lifetime shortening | C24: width/qubit management | D24: computer science | E24: 2026 | F24: ecdsa.fail f94f726 (Gajesh2007, 2026-05-31) | G24: Q | H24: nee | I24: - | J24: vuil | K24: 2 | L24: nee | M24: nee | N24: nee | O24: exact | P24: 0 | Q24: O(1) | R24: - | S24: - | T24: ja | U24: nee | V24: nee | W24: geen | X24: nee | Y24: midden | Z24: 3 | AA24: 3 | AB24: - | AC24: - | AD24: nee | AE24: ja | AF24: Early-uncompute the 512-bit lambda^2 product, run the y-multiply without it, recompute once to clear; and free the dead square temp at the fused affine instant. | effect: f94f726 affine low-scratch 2565->2459; 0620443 AFFINE_SQUARE_RECOMPUTE part of 2309->2025 | Pays one extra symmetric-square pair for the qubit saving. | AH24: =IF(H24="ja",1,0) -> 0 | AI24: =IF(J24="schoon",1,IF(J24="vuil",0.5,0)) -> 0.5 | AJ24: =K24/5 -> 0.4 | AK24: =IF(L24="ja",1,0) -> 0 | AL24: =IF(M24="ja",1,0) -> 0 | AM24: =IF(N24="ja",1,0) -> 0 | AN24: =IF(O24="exact",1,0) -> 1 | AO24: =IF(T24="ja",1,0) -> 1 | AP24: =IF(U24="ja",1,0) -> 0 | AQ24: =IF(V24="ja",1,0) -> 0 | AR24: =IF(W24="Bennett",1,IF(W24="meting",0.5,0)) -> 0 | AS24: =IF(X24="ja",1,0) -> 0 | AT24: =Z24/5 -> 0.6 | AU24: =AA24/5 -> 0.6
A25: G22 | B25: Karatsuba squaring (recursive, in place) | C25: multiplication | D25: mathematics | E25: 2026 | F25: ecdsa.fail 0399ebe (prasiddhnaik, 2026-06-02) | G25: T | H25: ja | I25: - | J25: schoon | K25: 3 | L25: nee | M25: nee | N25: nee | O25: exact | P25: 0 | Q25: O(n^1.58) | R25: O(n) | S25: O(n) | T25: ja | U25: nee | V25: nee | W25: Bennett | X25: nee | Y25: laag | Z25: 3 | AA25: 5 | AB25: 0 | AC25: 0 | AD25: ja | AE25: ja | AF25: Square via Karatsuba split x^2 = a^2 + 2ab<<k + b^2 with 2ab = t^2-a^2-b^2, t formed in place; recursion depth chosen by break-even (~60 bits); sequential half-square recombination to keep one product live. | effect: 717b405 sequential recombination -1.36% vs running best; 9e1ab6a second split level -1,211 T; schoolbook-vs-Karatsuba swaps used for peak (f94f726, 62c8115) | First read mention is 0399ebe ('Karatsuba x-tail' already present); origin not read (inferred earlier, ROUND84 lineage). b87bdf7 reports a 2-level recursion regressed on the 1153Q route. | AH25: =IF(H25="ja",1,0) -> 1 | AI25: =IF(J25="schoon",1,IF(J25="vuil",0.5,0)) -> 1 | AJ25: =K25/5 -> 0.6 | AK25: =IF(L25="ja",1,0) -> 0 | AL25: =IF(M25="ja",1,0) -> 0 | AM25: =IF(N25="ja",1,0) -> 0 | AN25: =IF(O25="exact",1,0) -> 1 | AO25: =IF(T25="ja",1,0) -> 1 | AP25: =IF(U25="ja",1,0) -> 0 | AQ25: =IF(V25="ja",1,0) -> 0 | AR25: =IF(W25="Bennett",1,IF(W25="meting",0.5,0)) -> 1 | AS25: =IF(X25="ja",1,0) -> 0 | AT25: =Z25/5 -> 0.6 | AU25: =AA25/5 -> 1
A26: G23 | B26: Chained-row square with held carries and split first reduction | C26: multiplication | D26: mathematics | E26: 2026 | F26: ecdsa.fail e3b5c51 (zuiris, 2026-10-20) | G26: T | H26: ja | I26: - | J26: schoon | K26: 3 | L26: nee | M26: ja | N26: nee | O26: benaderd | P26: per shot (lambda) | Q26: O(n^1.58) | R26: O(n) | S26: O(n) | T26: ja | U26: nee | V26: nee | W26: Bennett | X26: nee | Y26: laag | Z26: 3 | AA26: 5 | AB26: 0 | AC26: 0 | AD26: ja | AE26: ja | AF26: Add C = s^2 directly into the output with chained rows, holding carries and erasing them together, REDC-style one-digit frame travel, witness erase by measurement, and the square's first reduction split into digits. | effect: e3b5c51 G1M square -1,950 T (part of -0.601%); e4075d6 split first reduction -399 T | G1M uses a 21-bit overflow check (approximate); other parts exact per note. | AH26: =IF(H26="ja",1,0) -> 1 | AI26: =IF(J26="schoon",1,IF(J26="vuil",0.5,0)) -> 1 | AJ26: =K26/5 -> 0.6 | AK26: =IF(L26="ja",1,0) -> 0 | AL26: =IF(M26="ja",1,0) -> 1 | AM26: =IF(N26="ja",1,0) -> 0 | AN26: =IF(O26="exact",1,0) -> 0 | AO26: =IF(T26="ja",1,0) -> 1 | AP26: =IF(U26="ja",1,0) -> 0 | AQ26: =IF(V26="ja",1,0) -> 0 | AR26: =IF(W26="Bennett",1,IF(W26="meting",0.5,0)) -> 1 | AS26: =IF(X26="ja",1,0) -> 0 | AT26: =Z26/5 -> 0.6 | AU26: =AA26/5 -> 1
A27: G24 | B27: Pseudo-Mersenne (Solinas) fold reduction | C27: reduction | D27: mathematics | E27: 2026 | F27: ecdsa.fail f94f726 (Gajesh2007, 2026-05-31) | G27: T | H27: ja | I27: - | J27: schoon | K27: 2 | L27: nee | M27: nee | N27: nee | O27: exact | P27: 0 | Q27: O(n) | R27: O(n) | S27: O(n) | T27: ja | U27: nee | V27: nee | W27: Bennett | X27: ja | Y27: laag | Z27: 3 | AA27: 4 | AB27: 0 | AC27: 0 | AD27: ja | AE27: ja | AF27: Reduce mod p = 2^256 - (2^32+977) by folding high words times f into the low word; lazy/in-place variants, shift-by-22 forms, mask-free folds. | effect: f94f726 Solinas low-scratch 2333->2310 Q; 835298d in-place Solinas fold -13,360 T | Present from the baseline in some form (inferred). Shift-by-22 later replaced by a value-identical 22x double / sub / 22x halve walk to save peak (cbc35ea, 83e3b66). | AH27: =IF(H27="ja",1,0) -> 1 | AI27: =IF(J27="schoon",1,IF(J27="vuil",0.5,0)) -> 1 | AJ27: =K27/5 -> 0.4 | AK27: =IF(L27="ja",1,0) -> 0 | AL27: =IF(M27="ja",1,0) -> 0 | AM27: =IF(N27="ja",1,0) -> 0 | AN27: =IF(O27="exact",1,0) -> 1 | AO27: =IF(T27="ja",1,0) -> 1 | AP27: =IF(U27="ja",1,0) -> 0 | AQ27: =IF(V27="ja",1,0) -> 0 | AR27: =IF(W27="Bennett",1,IF(W27="meting",0.5,0)) -> 1 | AS27: =IF(X27="ja",1,0) -> 1 | AT27: =Z27/5 -> 0.6 | AU27: =AA27/5 -> 0.8
A28: G25 | B28: One fold per payload tick (deferred reduction) | C28: reduction | D28: mathematics | E28: 2026 | F28: ecdsa.fail e9cacd1 (krishparadox, 2026-10-09) | G28: T | H28: ja | I28: - | J28: schoon | K28: 2 | L28: nee | M28: nee | N28: nee | O28: benaderd | P28: per shot (lambda) | Q28: O(n) | R28: O(n) | S28: O(n) | T28: ja | U28: nee | V28: nee | W28: Bennett | X28: ja | Y28: laag | Z28: 3 | AA28: 4 | AB28: 0 | AC28: 0 | AD28: ja | AE28: ja | AF28: Do the three signed adds of a payload tick on a 259-bit integer with no folds in between, then fold once; later an in-place fold with a reduction digit of up to 10 bits. | effect: -1.45% vs running best (-11,416 T builder count); 4cb9cf0 in-place 10-bit fold within lever A | Fold window 56->57 bought back failing shots (+268 T). | AH28: =IF(H28="ja",1,0) -> 1 | AI28: =IF(J28="schoon",1,IF(J28="vuil",0.5,0)) -> 1 | AJ28: =K28/5 -> 0.4 | AK28: =IF(L28="ja",1,0) -> 0 | AL28: =IF(M28="ja",1,0) -> 0 | AM28: =IF(N28="ja",1,0) -> 0 | AN28: =IF(O28="exact",1,0) -> 0 | AO28: =IF(T28="ja",1,0) -> 1 | AP28: =IF(U28="ja",1,0) -> 0 | AQ28: =IF(V28="ja",1,0) -> 0 | AR28: =IF(W28="Bennett",1,IF(W28="meting",0.5,0)) -> 1 | AS28: =IF(X28="ja",1,0) -> 1 | AT28: =Z28/5 -> 0.6 | AU28: =AA28/5 -> 0.8
A29: G26 | B29: Conditional replay exploiting average-executed Toffoli | C29: scheduling/fusion | D29: computer science | E29: 2026 | F29: ecdsa.fail 4b7d727 (BitWonka, 2026-06-08) | G29: T | H29: nee | I29: - | J29: geen | K29: 2 | L29: nee | M29: ja | N29: ja | O29: exact | P29: 0 | Q29: - | R29: - | S29: - | T29: ja | U29: nee | V29: nee | W29: meting | X29: nee | Y29: laag | Z29: 3 | AA29: 3 | AB29: - | AC29: - | AD29: deels | AE29: ja | AF29: Put boundary steps under classical (measurement-outcome) conditions so their Toffolis execute on only a fraction of shots; the score counts average executed, not emitted, Toffoli. | effect: -3.49% vs running best (emitted 1,452,820 vs avg executed 1,404,058); 52c6b6b extension -1.20% | The author flags in the note that physical hardware would execute every emitted gate, so emitted count is the meaningful cost. b5fa90f notes that the nonce flips some Toffolis between depth 0 and depth 1, so cost is nonce-dependent. | AH29: =IF(H29="ja",1,0) -> 0 | AI29: =IF(J29="schoon",1,IF(J29="vuil",0.5,0)) -> 0 | AJ29: =K29/5 -> 0.4 | AK29: =IF(L29="ja",1,0) -> 0 | AL29: =IF(M29="ja",1,0) -> 1 | AM29: =IF(N29="ja",1,0) -> 1 | AN29: =IF(O29="exact",1,0) -> 1 | AO29: =IF(T29="ja",1,0) -> 1 | AP29: =IF(U29="ja",1,0) -> 0 | AQ29: =IF(V29="ja",1,0) -> 0 | AR29: =IF(W29="Bennett",1,IF(W29="meting",0.5,0)) -> 0.5 | AS29: =IF(X29="ja",1,0) -> 0 | AT29: =Z29/5 -> 0.6 | AU29: =AA29/5 -> 0.6
A30: G27 | B30: Classical offset point held in classical bit registers | C30: classical/precompute | D30: computer science | E30: 2026 | F30: ecdsa.fail af5abb1 (tob-joe, 2026-06-19) | G30: T | H30: nee | I30: - | J30: geen | K30: 1 | L30: nee | M30: ja | N30: ja | O30: exact | P30: 0 | Q30: - | R30: - | S30: - | T30: ja | U30: nee | V30: nee | W30: meting | X30: ja | Y30: laag | Z30: 2 | AA30: 4 | AB30: 0 | AC30: 0 | AD30: ja | AE30: ja | AF30: Keep the classical point Q as 2x256 classical bits, loading only transient quantum temps off-peak, so Q never occupies qubits at the GCD peak. | effect: stated as the decisive -512q product-min lever of trailmix-ludicrous (af5abb1) | Inferred: the challenge ABI already supplies Q classically (3616dbf), so the lever is not materialising it in qubits. Earlier routes may have done so (not verified). | AH30: =IF(H30="ja",1,0) -> 0 | AI30: =IF(J30="schoon",1,IF(J30="vuil",0.5,0)) -> 0 | AJ30: =K30/5 -> 0.2 | AK30: =IF(L30="ja",1,0) -> 0 | AL30: =IF(M30="ja",1,0) -> 1 | AM30: =IF(N30="ja",1,0) -> 1 | AN30: =IF(O30="exact",1,0) -> 1 | AO30: =IF(T30="ja",1,0) -> 1 | AP30: =IF(U30="ja",1,0) -> 0 | AQ30: =IF(V30="ja",1,0) -> 0 | AR30: =IF(W30="Bennett",1,IF(W30="meting",0.5,0)) -> 0.5 | AS30: =IF(X30="ja",1,0) -> 1 | AT30: =Z30/5 -> 0.4 | AU30: =AA30/5 -> 0.8
A31: G28 | B31: Multi-bit shift per GCD step (jump-GCD K=2 to 8-way barrel e<=7) | C31: inversion/GCD | D31: mathematics | E31: 2026 | F31: ecdsa.fail ca1cd1f (johnbxx, 2026-06-05) | G31: T+Q | H31: ja | I31: - | J31: schoon | K31: 3 | L31: nee | M31: nee | N31: nee | O31: exact | P31: 0 | Q31: O(n^2) | R31: O(n) | S31: O(n^2) | T31: ja | U31: nee | V31: ja | W31: Bennett | X31: nee | Y31: laag | Z31: 4 | AA31: 4 | AB31: 0 | AC31: 0 | AD31: ja | AE31: ja | AF31: Strip several trailing zeros per step (K=2 bounded shift / Schrottenloher jump-2; leapfrog 2-stage barrel e in [0,3]; lever A e<=7 with a per-rail (3,1) record) to cut step count. | effect: ca1cd1f iterations ~393->~259, -4.53% vs running best; 4cb9cf0 lever A 138->122 ticks, -16,281 T for +8 Q (-0.75%) | Barrel = 4-way (later 8-way) rotation from controlled reflections (1.5n-2 CSWAPs) plus a merged constant fold. Zero-fill rail barrel (e4075d6, -731.5 T) is a later refinement (RAIL_ZERO_FILL in mod.rs). | AH31: =IF(H31="ja",1,0) -> 1 | AI31: =IF(J31="schoon",1,IF(J31="vuil",0.5,0)) -> 1 | AJ31: =K31/5 -> 0.6 | AK31: =IF(L31="ja",1,0) -> 0 | AL31: =IF(M31="ja",1,0) -> 0 | AM31: =IF(N31="ja",1,0) -> 0 | AN31: =IF(O31="exact",1,0) -> 1 | AO31: =IF(T31="ja",1,0) -> 1 | AP31: =IF(U31="ja",1,0) -> 0 | AQ31: =IF(V31="ja",1,0) -> 1 | AR31: =IF(W31="Bennett",1,IF(W31="meting",0.5,0)) -> 1 | AS31: =IF(X31="ja",1,0) -> 0 | AT31: =Z31/5 -> 0.8 | AU31: =AA31/5 -> 0.8
A32: G29 | B32: Ping-pong fixed-schedule signed binary division | C32: inversion/GCD | D32: mathematics | E32: 2026 | F32: ecdsa.fail 3616dbf (teddyjfpender, 2026-08-21) | G32: T+Q | H32: ja | I32: - | J32: schoon | K32: 3 | L32: nee | M32: ja | N32: nee | O32: exact | P32: 0 | Q32: O(n^2) | R32: O(n) | S32: O(n^2) | T32: ja | U32: nee | V32: ja | W32: Bennett | X32: nee | Y32: laag | Z32: 4 | AA32: 4 | AB32: - | AC32: - | AD32: deels | AE32: ja | AF32: Two signed odd rails; the target alternates by round number; the low-bit predicate picks add/sub so (t+-s)/2 stays odd; one sign bit per round on a tape; multiply via the algebraic inverse recurrence T = 2T' + gS. | effect: -14.82% vs running best; Q 1150->1321 (up), T 1,284,776->952,707 | No data-dependent routing swaps. lambda ~1.2 at first (7bb8713), far below the trailmix route's 23.29. | AH32: =IF(H32="ja",1,0) -> 1 | AI32: =IF(J32="schoon",1,IF(J32="vuil",0.5,0)) -> 1 | AJ32: =K32/5 -> 0.6 | AK32: =IF(L32="ja",1,0) -> 0 | AL32: =IF(M32="ja",1,0) -> 1 | AM32: =IF(N32="ja",1,0) -> 0 | AN32: =IF(O32="exact",1,0) -> 1 | AO32: =IF(T32="ja",1,0) -> 1 | AP32: =IF(U32="ja",1,0) -> 0 | AQ32: =IF(V32="ja",1,0) -> 1 | AR32: =IF(W32="Bennett",1,IF(W32="meting",0.5,0)) -> 1 | AS32: =IF(X32="ja",1,0) -> 0 | AT32: =Z32/5 -> 0.8 | AU32: =AA32/5 -> 0.8
A33: G30 | B33: Interleaved walk/replay schedule | C33: scheduling/fusion | D33: computer science | E33: 2026 | F33: ecdsa.fail aac98e9 (0xrlawrence, 2026-08-21) | G33: T | H33: nee | I33: - | J33: geen | K33: 2 | L33: nee | M33: ja | N33: nee | O33: benaderd | P33: per shot (lambda) | Q33: - | R33: - | S33: - | T33: ja | U33: nee | V33: nee | W33: meting | X33: nee | Y33: laag | Z33: 3 | AA33: 3 | AB33: - | AC33: - | AD33: deels | AE33: ja | AF33: Replay coefficient round r while the walk is at round r (tape and payload only meet near the end), turning a flat peak into a ramp; budgeted chunk counts and segmented folds per round. | effect: aac98e9 1300->1279 Q (-1.18%); bc7a792 fused schedule 1316->1281 Q (-1.55% stated) | Two near-simultaneous independent versions (bc7a792 Akashneelesh 18:23, aac98e9 0xrlawrence 18:42 on 2026-08-21). | AH33: =IF(H33="ja",1,0) -> 0 | AI33: =IF(J33="schoon",1,IF(J33="vuil",0.5,0)) -> 0 | AJ33: =K33/5 -> 0.4 | AK33: =IF(L33="ja",1,0) -> 0 | AL33: =IF(M33="ja",1,0) -> 1 | AM33: =IF(N33="ja",1,0) -> 0 | AN33: =IF(O33="exact",1,0) -> 0 | AO33: =IF(T33="ja",1,0) -> 1 | AP33: =IF(U33="ja",1,0) -> 0 | AQ33: =IF(V33="ja",1,0) -> 0 | AR33: =IF(W33="Bennett",1,IF(W33="meting",0.5,0)) -> 0.5 | AS33: =IF(X33="ja",1,0) -> 0 | AT33: =Z33/5 -> 0.6 | AU33: =AA33/5 -> 0.6
A34: G31 | B34: Rails-only / payload-only early-tick reorder | C34: scheduling/fusion | D34: computer science | E34: 2026 | F34: ecdsa.fail 53986ea (BitWonka, 2026-10-07) | G34: T | H34: nee | I34: - | J34: geen | K34: 2 | L34: nee | M34: nee | N34: nee | O34: exact | P34: 0 | Q34: - | R34: - | S34: - | T34: ja | U34: nee | V34: nee | W34: geen | X34: nee | Y34: laag | Z34: 3 | AA34: 3 | AB34: 0 | AC34: 0 | AD34: ja | AE34: ja | AF34: For early ticks run the rails alone (one payload register live, no split adders), then replay the payload over the taped letters while the rails stay parked. | effect: -5.9k T (leapfrog.rs recipe comment); boundary retuned 73-77 | | AH34: =IF(H34="ja",1,0) -> 0 | AI34: =IF(J34="schoon",1,IF(J34="vuil",0.5,0)) -> 0 | AJ34: =K34/5 -> 0.4 | AK34: =IF(L34="ja",1,0) -> 0 | AL34: =IF(M34="ja",1,0) -> 0 | AM34: =IF(N34="ja",1,0) -> 0 | AN34: =IF(O34="exact",1,0) -> 1 | AO34: =IF(T34="ja",1,0) -> 1 | AP34: =IF(U34="ja",1,0) -> 0 | AQ34: =IF(V34="ja",1,0) -> 0 | AR34: =IF(W34="Bennett",1,IF(W34="meting",0.5,0)) -> 0 | AS34: =IF(X34="ja",1,0) -> 0 | AT34: =Z34/5 -> 0.6 | AU34: =AA34/5 -> 0.6
A35: G32 | B35: Terminal passenger loan / known-copy wire lending | C35: width/qubit management | D35: computer science | E35: 2026 | F35: ecdsa.fail 21a0ba3 (0xrlawrence, 2026-08-21) | G35: Q | H35: nee | I35: - | J35: vuil | K35: 2 | L35: nee | M35: nee | N35: nee | O35: exact | P35: 0 | Q35: O(1) | R35: - | S35: - | T35: ja | U35: nee | V35: nee | W35: geen | X35: nee | Y35: midden | Z35: 3 | AA35: 3 | AB35: 0 | AC35: 0 | AD35: ja | AE35: ja | AF35: At walk termination u,v in {+1,-1}, so non-sign wires are copies of the sign or constants; clear them with CX, free them across the replay, and restore them afterwards. | effect: -15 qubits (1317->1302), part of -1.15% vs running best | One-bit passenger loan by welttowelt preceded it (credited, not read). | AH35: =IF(H35="ja",1,0) -> 0 | AI35: =IF(J35="schoon",1,IF(J35="vuil",0.5,0)) -> 0.5 | AJ35: =K35/5 -> 0.4 | AK35: =IF(L35="ja",1,0) -> 0 | AL35: =IF(M35="ja",1,0) -> 0 | AM35: =IF(N35="ja",1,0) -> 0 | AN35: =IF(O35="exact",1,0) -> 1 | AO35: =IF(T35="ja",1,0) -> 1 | AP35: =IF(U35="ja",1,0) -> 0 | AQ35: =IF(V35="ja",1,0) -> 0 | AR35: =IF(W35="Bennett",1,IF(W35="meting",0.5,0)) -> 0 | AS35: =IF(X35="ja",1,0) -> 0 | AT35: =Z35/5 -> 0.6 | AU35: =AA35/5 -> 0.6
A36: G33 | B36: Skywalk min-source GCD in sum/difference frame | C36: inversion/GCD | D36: mathematics | E36: 2026 | F36: ecdsa.fail 4f0d213 (mochimodev, 2026-09-29) | G36: T+Q | H36: ja | I36: - | J36: schoon | K36: 3 | L36: nee | M36: nee | N36: nee | O36: exact | P36: 0 | Q36: O(n^2) | R36: O(n) | S36: O(n^2) | T36: ja | U36: nee | V36: ja | W36: Bennett | X36: nee | Y36: laag | Z36: 4 | AA36: 4 | AB36: - | AC36: - | AD36: deels | AE36: ja | AF36: Represent the pair as {u+v,u}; route the even rail to halving, replace the other by |O-H| with signed add/sub; orientation + sign-flip bits form a 3-symbol history (5 steps in 8 qubits). | effect: Q 1250->1174 at T 888,879->946,250; score -0.02% | ~390 steps vs ping-pong ~700. By Matt Zweil / MAI-A.A.E. | AH36: =IF(H36="ja",1,0) -> 1 | AI36: =IF(J36="schoon",1,IF(J36="vuil",0.5,0)) -> 1 | AJ36: =K36/5 -> 0.6 | AK36: =IF(L36="ja",1,0) -> 0 | AL36: =IF(M36="ja",1,0) -> 0 | AM36: =IF(N36="ja",1,0) -> 0 | AN36: =IF(O36="exact",1,0) -> 1 | AO36: =IF(T36="ja",1,0) -> 1 | AP36: =IF(U36="ja",1,0) -> 0 | AQ36: =IF(V36="ja",1,0) -> 1 | AR36: =IF(W36="Bennett",1,IF(W36="meting",0.5,0)) -> 1 | AS36: =IF(X36="ja",1,0) -> 0 | AT36: =Z36/5 -> 0.8 | AU36: =AA36/5 -> 0.8
A37: G34 | B37: Leapfrog route-free multi-step 2-adic walk | C37: inversion/GCD | D37: mathematics | E37: 2026 | F37: ecdsa.fail 53986ea (BitWonka, 2026-10-07) | G37: T+Q | H37: ja | I37: - | J37: schoon | K37: 3 | L37: nee | M37: ja | N37: nee | O37: benaderd | P37: per shot (lambda) | Q37: O(n^2) | R37: O(n) | S37: O(n^2) | T37: ja | U37: nee | V37: ja | W37: Bennett | X37: nee | Y37: laag | Z37: 4 | AA37: 4 | AB37: 0 | AC37: 0 | AD37: ja | AE37: ja | AF37: Odd rails alternate target roles on a fixed schedule; each tick does two forced add-halves, one deep/flat choice add-halve (top-window compare), and a barrel strip; 5-qubit letter per tick; 4 payload updates per leap. | effect: -9.74% vs running best (1,107,467,010 -> 999,570,880; Q 1170->1243, T 946,553->804,160) | lambda 14.4 at introduction. Later refinements: size-test choice rule, 138 ticks (c2fb64c), lever A 122 ticks (4cb9cf0). | AH37: =IF(H37="ja",1,0) -> 1 | AI37: =IF(J37="schoon",1,IF(J37="vuil",0.5,0)) -> 1 | AJ37: =K37/5 -> 0.6 | AK37: =IF(L37="ja",1,0) -> 0 | AL37: =IF(M37="ja",1,0) -> 1 | AM37: =IF(N37="ja",1,0) -> 0 | AN37: =IF(O37="exact",1,0) -> 0 | AO37: =IF(T37="ja",1,0) -> 1 | AP37: =IF(U37="ja",1,0) -> 0 | AQ37: =IF(V37="ja",1,0) -> 1 | AR37: =IF(W37="Bennett",1,IF(W37="meting",0.5,0)) -> 1 | AS37: =IF(X37="ja",1,0) -> 0 | AT37: =Z37/5 -> 0.8 | AU37: =AA37/5 -> 0.8
A38: G35 | B38: Merged last cell + barrel Montgomery-style op and minimal-AND (rank-bound) rewrites | C38: scheduling/fusion | D38: computer science | E38: 2026 | F38: ecdsa.fail 53986ea (BitWonka, 2026-10-07) | G38: T | H38: nee | I38: - | J38: geen | K38: 2 | L38: nee | M38: ja | N38: ja | O38: exact | P38: 0 | Q38: - | R38: - | S38: - | T38: ja | U38: nee | V38: nee | W38: meting | X38: nee | Y38: laag | Z38: 3 | AA38: 3 | AB38: 0 | AC38: 0 | AD38: ja | AE38: ja | AF38: Fuse the third add-halve and the 2^-e rotation into one op; rewrite small corrections to their AND rank lower bound (U4: u=x+ov+15sg -> (x+ov-sg)+16sg with 4 ANDs instead of 8; 10-AND table; XOR-of-existing-ANDs letters). | effect: U4 (0393770, mochimodev): -968 expected T; 242c0de nine exact rewrites: -3,872 T | Exact rewrites, verified on common inputs (242c0de) or all 64 helper inputs (U4). | AH38: =IF(H38="ja",1,0) -> 0 | AI38: =IF(J38="schoon",1,IF(J38="vuil",0.5,0)) -> 0 | AJ38: =K38/5 -> 0.4 | AK38: =IF(L38="ja",1,0) -> 0 | AL38: =IF(M38="ja",1,0) -> 1 | AM38: =IF(N38="ja",1,0) -> 1 | AN38: =IF(O38="exact",1,0) -> 1 | AO38: =IF(T38="ja",1,0) -> 1 | AP38: =IF(U38="ja",1,0) -> 0 | AQ38: =IF(V38="ja",1,0) -> 0 | AR38: =IF(W38="Bennett",1,IF(W38="meting",0.5,0)) -> 0.5 | AS38: =IF(X38="ja",1,0) -> 0 | AT38: =Z38/5 -> 0.6 | AU38: =AA38/5 -> 0.6
A39: G36 | B39: Tick-0 letter off the tape, short last tick, and size-test choice rule | C39: encoding/transcript | D39: information theory | E39: 2026 | F39: ecdsa.fail c2fb64c (krishparadox, 2026-10-08) | G39: Q | H39: ja | I39: - | J39: schoon | K39: 2 | L39: nee | M39: ja | N39: nee | O39: benaderd | P39: per shot (lambda) | Q39: O(n) | R39: O(n) | S39: O(n) | T39: ja | U39: nee | V39: ja | W39: Bennett | X39: nee | Y39: laag | Z39: 3 | AA39: 3 | AB39: 0 | AC39: 0 | AD39: ja | AE39: ja | AF39: Measure tick 0's letter away after its last read and re-derive it from the source rail at the walk end; make the last tick a choice-only 3-bit letter; use a one-chain size test in the deep/flat rule so slow walks finish one tick sooner. | effect: -1.04% vs running best (139->138 ticks, cap 1240->1237) | | AH39: =IF(H39="ja",1,0) -> 1 | AI39: =IF(J39="schoon",1,IF(J39="vuil",0.5,0)) -> 1 | AJ39: =K39/5 -> 0.4 | AK39: =IF(L39="ja",1,0) -> 0 | AL39: =IF(M39="ja",1,0) -> 1 | AM39: =IF(N39="ja",1,0) -> 0 | AN39: =IF(O39="exact",1,0) -> 0 | AO39: =IF(T39="ja",1,0) -> 1 | AP39: =IF(U39="ja",1,0) -> 0 | AQ39: =IF(V39="ja",1,0) -> 1 | AR39: =IF(W39="Bennett",1,IF(W39="meting",0.5,0)) -> 1 | AS39: =IF(X39="ja",1,0) -> 0 | AT39: =Z39/5 -> 0.6 | AU39: =AA39/5 -> 0.6
A40: G37 | B40: Census-mined dead-gate strip and CCX->CX/CZ downgrades | C40: approximation | D40: statistics | E40: 2026 | F40: ecdsa.fail dcbafc5 (mochimodev, 2026-07-11) | G40: T | H40: nee | I40: - | J40: geen | K40: 1 | L40: nee | M40: nee | N40: nee | O40: benaderd | P40: per shot (lambda) | Q40: - | R40: - | S40: - | T40: ja | U40: nee | V40: ja | W40: geen | X40: nee | Y40: laag | Z40: 2 | AA40: 3 | AB40: 0 | AC40: 0 | AD40: ja | AE40: ja | AF40: Simulate the exact stream on many random valid inputs, record per Toffoli whether its AND ever fired or always equalled one control, then delete or downgrade by op-index table bound to the stream hash. | effect: dcbafc5 2,101 CCX (-0.15%); 3493c83 action mask 16,850 actions; 02146ca 1e9-input census 9,268 dead + 2,050 downgrades; 076f110 156 cuts on 24.2M shots (-148.5 T); 46ae05c failure-priced k<=7 (-317.5 T) | Sampled-exact, not proved: 076f110 shows 86 of 242 candidates clean at 8M shots fire by 24M. b5fa90f: true greedy re-evaluation of marginal coverage under a risk budget. dcbafc5 itsel | AH40: =IF(H40="ja",1,0) -> 0 | AI40: =IF(J40="schoon",1,IF(J40="vuil",0.5,0)) -> 0 | AJ40: =K40/5 -> 0.2 | AK40: =IF(L40="ja",1,0) -> 0 | AL40: =IF(M40="ja",1,0) -> 0 | AM40: =IF(N40="ja",1,0) -> 0 | AN40: =IF(O40="exact",1,0) -> 0 | AO40: =IF(T40="ja",1,0) -> 1 | AP40: =IF(U40="ja",1,0) -> 0 | AQ40: =IF(V40="ja",1,0) -> 1 | AR40: =IF(W40="Bennett",1,IF(W40="meting",0.5,0)) -> 0 | AS40: =IF(X40="ja",1,0) -> 0 | AT40: =Z40/5 -> 0.4 | AU40: =AA40/5 -> 0.6
A41: G38 | B41: Proved exact op-stream simplification passes | C41: classical/precompute | D41: computer science | E41: 2026 | F41: ecdsa.fail 66d8c54 (gopikannappan, 2026-06-19) | G41: T | H41: nee | I41: - | J41: geen | K41: 1 | L41: nee | M41: ja | N41: nee | O41: exact | P41: 0 | Q41: - | R41: - | S41: - | T41: ja | U41: nee | V41: nee | W41: meting | X41: ja | Y41: laag | Z41: 2 | AA41: 4 | AB41: 0 | AC41: 0 | AD41: ja | AE41: ja | AF41: Generic post-passes that prove CCX controls constant or support-redundant (classical constant propagation, affine/quadratic/truth-table support identities, consumed-only-by-phase cond pass, constant-Hmr zero_force, clear-before-reset y33) and drop or weaken them. | effect: 66d8c54 -1,254 executed T (679 dropped + 575 to CX); 427ac4c 70 proved cuts + 2 classical passes (part of -1,243 T) | Exact by construction. Includes swadhin 6f8aba7 exact affine 'bridges' (exhaustive window checks) as a hand-made instance. | AH41: =IF(H41="ja",1,0) -> 0 | AI41: =IF(J41="schoon",1,IF(J41="vuil",0.5,0)) -> 0 | AJ41: =K41/5 -> 0.2 | AK41: =IF(L41="ja",1,0) -> 0 | AL41: =IF(M41="ja",1,0) -> 1 | AM41: =IF(N41="ja",1,0) -> 0 | AN41: =IF(O41="exact",1,0) -> 1 | AO41: =IF(T41="ja",1,0) -> 1 | AP41: =IF(U41="ja",1,0) -> 0 | AQ41: =IF(V41="ja",1,0) -> 0 | AR41: =IF(W41="Bennett",1,IF(W41="meting",0.5,0)) -> 0.5 | AS41: =IF(X41="ja",1,0) -> 1 | AT41: =Z41/5 -> 0.4 | AU41: =AA41/5 -> 0.8
...

Sheet Ongebruikt
A1: Technieken die de leader niet gebruikt (incl. recent academisch werk)
A3: ID | B3: Techniek | C3: Categorie | D3: Vakgebied | E3: Jaar | F3: Bron | G3: Primair doel | H3: Vast aantal qubits nodig | I3: Extra qubits @256 (schatting) | J3: Ancilla-type | K3: Coherentie-eis (1-5) | L3: Verstrengeling met data nodig | M3: Mid-circuit meting | N3: Klassieke feedforward | O3: Exact / benaderd | P3: Foutkans | Q3: Toffoli-schaal | R3: Qubit-schaal | S3: Diepte-schaal | T3: Challenge-gateset ok | U3: Rotaties nodig | V3: Data-afhankelijk pad | W3: Uncompute-methode | X3: Vooraf berekende tabellen | Y3: Fase-risico | Z3: Complexiteit (1-5) | AA3: Volwassenheid (1-5) | AB3: T-effect op leader (%) | AC3: Q-effect op leader (qubits) | AD3: In leader | AE3: Elders gebruikt | AF3: Opmerking | AH3: f:vast | AI3: f:ancilla | AJ3: f:coherentie | AK3: f:verstrengeling | AL3: f:meting | AM3: f:feedforward | AN3: f:exact | AO3: f:gateset | AP3: f:rotaties | AQ3: f:data-afh | AR3: f:uncompute | AS3: f:tabellen | AT3: f:complexiteit | AU3: f:volwassenheid
A4: U01 | B4: Half-delta divsteps (Bernstein-Yang hddivsteps) | C4: inversion | D4: mathematics | E4: 2021 | F4: Bernstein-Yang 2019; sipa safegcd bounds | G4: exactness | H4: ja | I4: 500 | J4: schoon | K4: 3 | L4: nee | M4: nee | N4: nee | O4: exact | P4: 0 | Q4: O(n^2) | R4: O(n) | S4: O(n^2) | T4: ja | U4: nee | V4: ja | W4: Bennett | X4: nee | Y4: laag | Z4: 3 | AA4: 4 | AB4: 40 | AC4: 500 | AD4: nee | AE4: ja | AF4: measured: 591 fixed steps, 3000/3000 inverses correct, rail envelope median+7 bits; transcript ~2 bits/step | AH4: =IF(H4="ja",1,0) -> 1 | AI4: =IF(J4="schoon",1,IF(J4="vuil",0.5,0)) -> 1 | AJ4: =K4/5 -> 0.6 | AK4: =IF(L4="ja",1,0) -> 0 | AL4: =IF(M4="ja",1,0) -> 0 | AM4: =IF(N4="ja",1,0) -> 0 | AN4: =IF(O4="exact",1,0) -> 1 | AO4: =IF(T4="ja",1,0) -> 1 | AP4: =IF(U4="ja",1,0) -> 0 | AQ4: =IF(V4="ja",1,0) -> 1 | AR4: =IF(W4="Bennett",1,IF(W4="meting",0.5,0)) -> 1 | AS4: =IF(X4="ja",1,0) -> 0 | AT4: =Z4/5 -> 0.6 | AU4: =AA4/5 -> 0.8
A5: U02 | B5: safegcd jump matrices (62-step batches from low bits) | C5: inversion | D5: mathematics | E5: 2019 | F5: Bernstein-Yang 2019 | G5: T | H5: ja | I5: 250 | J5: schoon | K5: 3 | L5: nee | M5: nee | N5: nee | O5: exact | P5: 0 | Q5: O(n^2) | R5: O(n) | S5: O(n^2/w) | T5: ja | U5: nee | V5: ja | W5: Bennett | X5: nee | Y5: laag | Z5: 4 | AA5: 3 | AB5: 60 | AC5: 250 | AD5: nee | AE5: nee | AF5: matrix application costs ~4 n-bit products per batch, ~3x the stepwise adds per bit (crossfield doc) | AH5: =IF(H5="ja",1,0) -> 1 | AI5: =IF(J5="schoon",1,IF(J5="vuil",0.5,0)) -> 1 | AJ5: =K5/5 -> 0.6 | AK5: =IF(L5="ja",1,0) -> 0 | AL5: =IF(M5="ja",1,0) -> 0 | AM5: =IF(N5="ja",1,0) -> 0 | AN5: =IF(O5="exact",1,0) -> 1 | AO5: =IF(T5="ja",1,0) -> 1 | AP5: =IF(U5="ja",1,0) -> 0 | AQ5: =IF(V5="ja",1,0) -> 1 | AR5: =IF(W5="Bennett",1,IF(W5="meting",0.5,0)) -> 1 | AS5: =IF(X5="ja",1,0) -> 0 | AT5: =Z5/5 -> 0.8 | AU5: =AA5/5 -> 0.6
A6: U03 | B6: k-ary GCD with small-multiplier table (Sorenson/Weber) | C6: inversion | D6: mathematics | E6: 1994 | F6: Sorenson 1994; Weber 1995; Sedjelmaci-Lavault 2014 | G6: T | H6: ja | I6: 300 | J6: schoon | K6: 3 | L6: nee | M6: nee | N6: nee | O6: exact | P6: 0 | Q6: O(n^2) | R6: O(n) | S6: O(n^2) | T6: ja | U6: nee | V6: ja | W6: Bennett | X6: ja | Y6: midden | Z6: 4 | AA6: 2 | AB6: 150 | AC6: 300 | AD6: nee | AE6: nee | AF6: a*u+b*v with quantum a,b ~ 2 adds per bit vs leader ~0.66; spurious factors need a second inverse | AH6: =IF(H6="ja",1,0) -> 1 | AI6: =IF(J6="schoon",1,IF(J6="vuil",0.5,0)) -> 1 | AJ6: =K6/5 -> 0.6 | AK6: =IF(L6="ja",1,0) -> 0 | AL6: =IF(M6="ja",1,0) -> 0 | AM6: =IF(N6="ja",1,0) -> 0 | AN6: =IF(O6="exact",1,0) -> 1 | AO6: =IF(T6="ja",1,0) -> 1 | AP6: =IF(U6="ja",1,0) -> 0 | AQ6: =IF(V6="ja",1,0) -> 1 | AR6: =IF(W6="Bennett",1,IF(W6="meting",0.5,0)) -> 1 | AS6: =IF(X6="ja",1,0) -> 1 | AT6: =Z6/5 -> 0.8 | AU6: =AA6/5 -> 0.4
A7: U04 | B7: Lehmer / half-GCD (Schonhage, Stehle-Zimmermann) | C7: inversion | D7: mathematics | E7: 1971 | F7: Schonhage 1971; Stehle-Zimmermann 2004 | G7: T | H7: ja | I7: 512 | J7: schoon | K7: 4 | L7: nee | M7: nee | N7: nee | O7: exact | P7: 0 | Q7: O(M(n) log n) | R7: O(n) | S7: O(n log n) | T7: ja | U7: nee | V7: ja | W7: Bennett | X7: nee | Y7: laag | Z7: 5 | AA7: 2 | AB7: 200 | AC7: 512 | AD7: nee | AE7: nee | AF7: asymptotic only; at n=256 matrix products dominate | AH7: =IF(H7="ja",1,0) -> 1 | AI7: =IF(J7="schoon",1,IF(J7="vuil",0.5,0)) -> 1 | AJ7: =K7/5 -> 0.8 | AK7: =IF(L7="ja",1,0) -> 0 | AL7: =IF(M7="ja",1,0) -> 0 | AM7: =IF(N7="ja",1,0) -> 0 | AN7: =IF(O7="exact",1,0) -> 1 | AO7: =IF(T7="ja",1,0) -> 1 | AP7: =IF(U7="ja",1,0) -> 0 | AQ7: =IF(V7="ja",1,0) -> 1 | AR7: =IF(W7="Bennett",1,IF(W7="meting",0.5,0)) -> 1 | AS7: =IF(X7="ja",1,0) -> 0 | AT7: =Z7/5 -> 1 | AU7: =AA7/5 -> 0.4
A8: U05 | B8: Extended Euclid with quotients + register sharing (Proos-Zalka) | C8: inversion | D8: mathematics | E8: 2003 | F8: Proos-Zalka 2003; arXiv 2604.02311 (2026) | G8: Q | H8: ja | I8: -200 | J8: schoon | K8: 5 | L8: nee | M8: nee | N8: nee | O8: exact | P8: 0 | Q8: O(n^2 log n) | R8: O(n) | S8: O(n^2 log n) | T8: ja | U8: nee | V8: ja | W8: Bennett | X8: nee | Y8: laag | Z8: 5 | AA8: 3 | AB8: 3000 | AC8: -200 | AD8: nee | AE8: ja | AF8: 2604.02311: ~204 n^2 log2 n T per inversion (~107M at n=256) | AH8: =IF(H8="ja",1,0) -> 1 | AI8: =IF(J8="schoon",1,IF(J8="vuil",0.5,0)) -> 1 | AJ8: =K8/5 -> 1 | AK8: =IF(L8="ja",1,0) -> 0 | AL8: =IF(M8="ja",1,0) -> 0 | AM8: =IF(N8="ja",1,0) -> 0 | AN8: =IF(O8="exact",1,0) -> 1 | AO8: =IF(T8="ja",1,0) -> 1 | AP8: =IF(U8="ja",1,0) -> 0 | AQ8: =IF(V8="ja",1,0) -> 1 | AR8: =IF(W8="Bennett",1,IF(W8="meting",0.5,0)) -> 1 | AS8: =IF(X8="ja",1,0) -> 0 | AT8: =Z8/5 -> 1 | AU8: =AA8/5 -> 0.6
A9: U06 | B9: Kaliski Montgomery inverse with comparisons | C9: inversion | D9: mathematics | E9: 1995 | F9: Kaliski 1995; Roetteler et al. 2017 | G9: T | H9: ja | I9: 300 | J9: schoon | K9: 3 | L9: nee | M9: nee | N9: nee | O9: exact | P9: 0 | Q9: O(n^2) | R9: O(n) | S9: O(n^2) | T9: ja | U9: nee | V9: ja | W9: Bennett | X9: nee | Y9: laag | Z9: 3 | AA9: 5 | AB9: 150 | AC9: 300 | AD9: nee | AE9: ja | AF9: full-width compare + swap per step; Roetteler: 4 inversion calls per point add | AH9: =IF(H9="ja",1,0) -> 1 | AI9: =IF(J9="schoon",1,IF(J9="vuil",0.5,0)) -> 1 | AJ9: =K9/5 -> 0.6 | AK9: =IF(L9="ja",1,0) -> 0 | AL9: =IF(M9="ja",1,0) -> 0 | AM9: =IF(N9="ja",1,0) -> 0 | AN9: =IF(O9="exact",1,0) -> 1 | AO9: =IF(T9="ja",1,0) -> 1 | AP9: =IF(U9="ja",1,0) -> 0 | AQ9: =IF(V9="ja",1,0) -> 1 | AR9: =IF(W9="Bennett",1,IF(W9="meting",0.5,0)) -> 1 | AS9: =IF(X9="ja",1,0) -> 0 | AT9: =Z9/5 -> 0.6 | AU9: =AA9/5 -> 1
